<?xml version="1.0" encoding="utf-8"?>
<!-- This URDF was automatically created by SolidWorks to URDF Exporter! Originally created by Stephen Brawner (brawner@gmail.com) 
     Commit Version: 1.6.0-4-g7f85cfe  Build Version: 1.6.7995.38578
     For more information, please see http://wiki.ros.org/sw_urdf_exporter -->
<robot
  name="minidog">
  <link
    name="base">
    <inertial>
      <origin
        xyz="0.00821482 0.00020218 0.00424442"
        rpy="0 0 0" />
      <mass
        value="2.7673" />
      <inertia
        ixx="0.00998124"
        ixy="9.82E-06"
        ixz="-0.00257876"
        iyy="0.02546149"
        iyz="-1.318E-05"
        izz="0.02812534" />
    </inertial>
    <visual>
      <origin
        xyz="0 0 0"
        rpy="0 0 0" />
      <geometry>
        <mesh
          filename="../meshes/base.STL" />
      </geometry>
      <material
        name="">
        <color
          rgba="0.75294 0.75294 0.75294 1" />
      </material>
    </visual>
    <collision>
      <origin
        xyz="0 0 0"
        rpy="0 0 0" />
      <geometry>
        <box size="0.194 0.16 0.07" />
      </geometry>
    </collision>
    <collision>
      <origin
        xyz="0.2 0 0.03"
        rpy="0 1.57079632 0" />
      <geometry>
        <cylinder length="0.025" radius="0.02"/>
      </geometry>
    </collision>
  </link>
  <link
    name="lf_hip">
    <inertial>
      <origin
        xyz="0.03515121 -0.00140177 9.224E-05"
        rpy="0 0 0" />
      <mass
        value="0.28323" />
      <inertia
        ixx="8.573E-05"
        ixy="1.77E-06"
        ixz="-9E-08"
        iyy="9.68E-05"
        iyz="4.9E-07"
        izz="9.864E-05" />
    </inertial>
    <visual>
      <origin
        xyz="0 0 0"
        rpy="0 0 0" />
      <geometry>
        <mesh
          filename="../meshes/lf_hip.STL" />
      </geometry>
      <material
        name="">
        <color
          rgba="0.75294 0.75294 0.75294 1" />
      </material>
    </visual>
    <collision>
      <origin
        xyz="0.03515121 -0.00140177 9.224E-05"
        rpy="1.57079632 0 0" />
      <geometry>
        <cylinder radius="0.028" length="0.04" />
      </geometry>
    </collision>
  </link>
  <joint
    name="lf_hip_joint"
    type="revolute">
    <origin
      xyz="0.097 0.04 0"
      rpy="0 0 0" />
    <parent
      link="base" />
    <child
      link="lf_hip" />
    <axis
      xyz="1 0 0" />
    <limit
      lower="-0.087222"
      upper="0.087222"
      effort="6"
      velocity="10.467" />
  </joint>
  <link
    name="lf_thigh">
    <inertial>
      <origin
        xyz="-0.00010595 0.05512752 -0.00907793"
        rpy="0 0 0" />
      <mass
        value="0.42421" />
      <inertia
        ixx="0.00057282"
        ixy="7.38E-06"
        ixz="-1.032E-05"
        iyy="0.00042725"
        iyz="0.00010651"
        izz="0.0002817" />
    </inertial>
    <visual>
      <origin
        xyz="0 0 0"
        rpy="0 0 0" />
      <geometry>
        <mesh
          filename="../meshes/lf_thigh.STL" />
      </geometry>
      <material
        name="">
        <color
          rgba="0.75294 0.75294 0.75294 1" />
      </material>
    </visual>
    <collision>
      <origin
        xyz="-0.00010595 0.05512752 -0.00907793"
        rpy="0 0 0" />
      <geometry>
        <box size="0.03 0.03 0.05" />
      </geometry>
    </collision>
  </link>
  <joint
    name="lf_thigh_joint"
    type="revolute">
    <origin
      xyz="0.037 0.017 0"
      rpy="0 0 0" />
    <parent
      link="lf_hip" />
    <child
      link="lf_thigh" />
    <axis
      xyz="0 1 0" />
    <limit
      lower="-2.6167"
      upper="2.6167"
      effort="6"
      velocity="10.467" />
  </joint>
  <link
    name="lf_calf">
    <inertial>
      <origin
        xyz="0.00275232 0 -0.02972173"
        rpy="0 0 0" />
      <mass
        value="0.045248" />
      <inertia
        ixx="7.175E-05"
        ixy="0"
        ixz="3.98E-06"
        iyy="7.314E-05"
        iyz="0"
        izz="3.66E-06" />
    </inertial>
    <visual>
      <origin
        xyz="0 0 0"
        rpy="0 0 0" />
      <geometry>
        <mesh
          filename="../meshes/lf_calf.STL" />
      </geometry>
      <material
        name="">
        <color
          rgba="0.75294 0.75294 0.75294 1" />
      </material>
    </visual>
    <collision>
      <origin
        xyz="0.00275232 0 -0.02972173"
        rpy="0 0 0" />
      <geometry>
        <box size="0.015 0.015 0.05" />
      </geometry>
    </collision>
  </link>
  <joint
    name="lf_calf_joint"
    type="revolute">
    <origin
      xyz="0 0.081 -0.105"
      rpy="0 0 0" />
    <parent
      link="lf_thigh" />
    <child
      link="lf_calf" />
    <axis
      xyz="0 1 0" />
    <limit
      lower="-2.5469"
      upper="-0.48844"
      effort="6"
      velocity="10.467" />
  </joint>
  <link
    name="lf_foot">
    <inertial>
      <origin
        xyz="-0.0005743 -0.00010766 -0.0027789"
        rpy="0 0 0" />
      <mass
        value="0.014945" />
      <inertia
        ixx="1E-06"
        ixy="0"
        ixz="6E-08"
        iyy="1.06E-06"
        iyz="0"
        izz="1.3E-06" />
    </inertial>
    <visual>
      <origin
        xyz="0 0 0"
        rpy="0 0 0" />
      <geometry>
        <mesh
          filename="../meshes/lf_foot.STL" />
      </geometry>
      <material
        name="">
        <color
          rgba="0.75294 0.75294 0.75294 1" />
      </material>
    </visual>
    <collision>
      <origin
        xyz="-0.0005743 -0.00010766 -0.0027789"
        rpy="0 0 0" />
      <geometry>
        <sphere radius="0.015" />
      </geometry>
    </collision>
  </link>
  <joint
    name="lf_foot_joint"
    type="fixed">
    <origin
      xyz="0 0 -0.12589"
      rpy="0 0 0" />
    <parent
      link="lf_calf" />
    <child
      link="lf_foot" />
    <axis
      xyz="0 0 0" />
  </joint>
  <link
    name="rf_hip">
    <inertial>
      <origin
        xyz="0.03515121 0.00140177 -9.224E-05"
        rpy="0 0 0" />
      <mass
        value="0.28323" />
      <inertia
        ixx="8.573E-05"
        ixy="-1.77E-06"
        ixz="9E-08"
        iyy="9.68E-05"
        iyz="4.9E-07"
        izz="9.864E-05" />
    </inertial>
    <visual>
      <origin
        xyz="0 0 0"
        rpy="0 0 0" />
      <geometry>
        <mesh
          filename="../meshes/rf_hip.STL" />
      </geometry>
      <material
        name="">
        <color
          rgba="0.75294 0.75294 0.75294 1" />
      </material>
    </visual>
    <collision>
      <origin
        xyz="0.03515121 0.00140177 -9.224E-05"
        rpy="1.57079632 0 0" />
      <geometry>
        <cylinder radius="0.028" length="0.04" />
      </geometry>
    </collision>
  </link>
  <joint
    name="rf_hip_joint"
    type="revolute">
    <origin
      xyz="0.097 -0.04 0"
      rpy="0 0 0" />
    <parent
      link="base" />
    <child
      link="rf_hip" />
    <axis
      xyz="1 0 0" />
    <limit
      lower="-0.087222"
      upper="0.087222"
      effort="6"
      velocity="10.467" />
  </joint>
  <link
    name="rf_thigh">
    <inertial>
      <origin
        xyz="6.646E-05 -0.05491633 -0.00912824"
        rpy="0 0 0" />
      <mass
        value="0.42559" />
      <inertia
        ixx="0.00057366"
        ixy="-9.7E-06"
        ixz="-1.102E-05"
        iyy="0.00042739"
        iyz="-0.00010638"
        izz="0.00028519" />
    </inertial>
    <visual>
      <origin
        xyz="0 0 0"
        rpy="0 0 0" />
      <geometry>
        <mesh
          filename="../meshes/rf_thigh.STL" />
      </geometry>
      <material
        name="">
        <color
          rgba="0.75294 0.75294 0.75294 1" />
      </material>
    </visual>
    <collision>
      <origin
        xyz="6.646E-05 -0.05491633 -0.00912824"
        rpy="0 0 0" />
      <geometry>
        <box size="0.03 0.03 0.05" />
      </geometry>
    </collision>
  </link>
  <joint
    name="rf_thigh_joint"
    type="revolute">
    <origin
      xyz="0.037 -0.017 0"
      rpy="0 0 0" />
    <parent
      link="rf_hip" />
    <child
      link="rf_thigh" />
    <axis
      xyz="0 1 0" />
    <limit
      lower="-2.6167"
      upper="2.6167"
      effort="6"
      velocity="10.467" />
  </joint>
  <link
    name="rf_calf">
    <inertial>
      <origin
        xyz="0.00275232 0 -0.02972173"
        rpy="0 0 0" />
      <mass
        value="0.045248" />
      <inertia
        ixx="7.175E-05"
        ixy="0"
        ixz="3.98E-06"
        iyy="7.314E-05"
        iyz="0"
        izz="3.66E-06" />
    </inertial>
    <visual>
      <origin
        xyz="0 0 0"
        rpy="0 0 0" />
      <geometry>
        <mesh
          filename="../meshes/rf_calf.STL" />
      </geometry>
      <material
        name="">
        <color
          rgba="0.75294 0.75294 0.75294 1" />
      </material>
    </visual>
    <collision>
      <origin
        xyz="0.00275232 0 -0.02972173"
        rpy="0 0 0" />
      <geometry>
        <box size="0.03 0.03 0.05" />
      </geometry>
    </collision>
  </link>
  <joint
    name="rf_calf_joint"
    type="revolute">
    <origin
      xyz="0 -0.081 -0.105"
      rpy="0 0 0" />
    <parent
      link="rf_thigh" />
    <child
      link="rf_calf" />
    <axis
      xyz="0 1 0" />
    <limit
      lower="-2.5469"
      upper="-0.48844"
      effort="6"
      velocity="10.467" />
  </joint>
  <link
    name="rf_foot">
    <inertial>
      <origin
        xyz="-0.0005743 -0.00010766 -0.0027789"
        rpy="0 0 0" />
      <mass
        value="0.014945" />
      <inertia
        ixx="1E-06"
        ixy="0"
        ixz="6E-08"
        iyy="1.06E-06"
        iyz="0"
        izz="1.3E-06" />
    </inertial>
    <visual>
      <origin
        xyz="0 0 0"
        rpy="0 0 0" />
      <geometry>
        <mesh
          filename="../meshes/rf_foot.STL" />
      </geometry>
      <material
        name="">
        <color
          rgba="0.75294 0.75294 0.75294 1" />
      </material>
    </visual>
     <collision>
      <origin
        xyz="-0.0005743 -0.00010766 -0.0027789"
        rpy="0 0 0" />
      <geometry>
        <sphere radius="0.015" />
      </geometry>
    </collision>
  </link>
  <joint
    name="rf_foot_joint"
    type="fixed">
    <origin
      xyz="0 0 -0.12589"
      rpy="0 0 0" />
    <parent
      link="rf_calf" />
    <child
      link="rf_foot" />
    <axis
      xyz="0 0 0" />
  </joint>
  <link
    name="lr_hip">
    <inertial>
      <origin
        xyz="-0.03515121 -0.00140177 -9.224E-05"
        rpy="0 0 0" />
      <mass
        value="0.28323" />
      <inertia
        ixx="8.573E-05"
        ixy="-1.77E-06"
        ixz="-9E-08"
        iyy="9.68E-05"
        iyz="-4.9E-07"
        izz="9.864E-05" />
    </inertial>
    <visual>
      <origin
        xyz="0 0 0"
        rpy="0 0 0" />
      <geometry>
        <mesh
          filename="../meshes/lr_hip.STL" />
      </geometry>
      <material
        name="">
        <color
          rgba="0.75294 0.75294 0.75294 1" />
      </material>
    </visual>
    <collision>
      <origin
        xyz="-0.03515121 -0.00140177 -9.224E-05"
        rpy="1.57079632 0 0" />
      <geometry>
        <cylinder radius="0.028" length="0.04" />
      </geometry>
    </collision>
  </link>
  <joint
    name="lr_hip_joint"
    type="revolute">
    <origin
      xyz="-0.097 0.04 0"
      rpy="0 0 0" />
    <parent
      link="base" />
    <child
      link="lr_hip" />
    <axis
      xyz="1 0 0" />
    <limit
      lower="-0.087222"
      upper="0.087222"
      effort="6"
      velocity="10.467" />
  </joint>
  <link
    name="lr_thigh">
    <inertial>
      <origin
        xyz="-0.00043375 0.05495689 -0.00971555"
        rpy="0 0 0" />
      <mass
        value="0.41571" />
      <inertia
        ixx="0.00055768"
        ixy="5.8E-07"
        ixz="-6.79E-06"
        iyy="0.00041688"
        iyz="9.683E-05"
        izz="0.00027342" />
    </inertial>
    <visual>
      <origin
        xyz="0 0 0"
        rpy="0 0 0" />
      <geometry>
        <mesh
          filename="../meshes/lr_thigh.STL" />
      </geometry>
      <material
        name="">
        <color
          rgba="0.75294 0.75294 0.75294 1" />
      </material>
    </visual>
    <collision>
      <origin
        xyz="-0.00043375 0.05495689 -0.00971555"
        rpy="0 0 0" />
      <geometry>
        <box size="0.03 0.03 0.05" />
      </geometry>
    </collision>
  </link>
  <joint
    name="lr_thigh_joint"
    type="revolute">
    <origin
      xyz="-0.037 0.017 0"
      rpy="0 0 0" />
    <parent
      link="lr_hip" />
    <child
      link="lr_thigh" />
    <axis
      xyz="0 1 0" />
    <limit
      lower="-2.6167"
      upper="2.6167"
      effort="6"
      velocity="10.467" />
  </joint>
  <link
    name="lr_calf">
    <inertial>
      <origin
        xyz="0.00275232 0 -0.02972173"
        rpy="0 0 0" />
      <mass
        value="0.045248" />
      <inertia
        ixx="7.175E-05"
        ixy="0"
        ixz="3.98E-06"
        iyy="7.314E-05"
        iyz="0"
        izz="3.66E-06" />
    </inertial>
    <visual>
      <origin
        xyz="0 0 0"
        rpy="0 0 0" />
      <geometry>
        <mesh
          filename="../meshes/lr_calf.STL" />
      </geometry>
      <material
        name="">
        <color
          rgba="0.75294 0.75294 0.75294 1" />
      </material>
    </visual>
    <collision>
      <origin
        xyz="0.00275232 0 -0.02972173"
        rpy="0 0 0" />
      <geometry>
        <box size="0.015 0.015 0.05" />
      </geometry>
    </collision>
  </link>
  <joint
    name="lr_calf_joint"
    type="revolute">
    <origin
      xyz="0 0.081 -0.105"
      rpy="0 0 0" />
    <parent
      link="lr_thigh" />
    <child
      link="lr_calf" />
    <axis
      xyz="0 1 0" />
    <limit
      lower="-2.5469"
      upper="-0.48844"
      effort="6"
      velocity="10.467" />
  </joint>
  <link
    name="lr_foot">
    <inertial>
      <origin
        xyz="-0.0005743 -0.00010766 -0.0027789"
        rpy="0 0 0" />
      <mass
        value="0.014945" />
      <inertia
        ixx="1E-06"
        ixy="0"
        ixz="6E-08"
        iyy="1.06E-06"
        iyz="0"
        izz="1.3E-06" />
    </inertial>
    <visual>
      <origin
        xyz="0 0 0"
        rpy="0 0 0" />
      <geometry>
        <mesh
          filename="../meshes/lr_foot.STL" />
      </geometry>
      <material
        name="">
        <color
          rgba="0.75294 0.75294 0.75294 1" />
      </material>
    </visual>
    <collision>
      <origin
        xyz="-0.0005743 -0.00010766 -0.0027789"
        rpy="0 0 0" />
      <geometry>
        <sphere radius="0.015" />
      </geometry>
    </collision>
  </link>
  <joint
    name="lr_foot_joint"
    type="fixed">
    <origin
      xyz="0 0 -0.12589"
      rpy="0 0 0" />
    <parent
      link="lr_calf" />
    <child
      link="lr_foot" />
    <axis
      xyz="0 0 0" />
  </joint>
  <link
    name="rr_hip">
    <inertial>
      <origin
        xyz="-0.03515121 0.00140177 9.224E-05"
        rpy="0 0 0" />
      <mass
        value="0.28323" />
      <inertia
        ixx="8.573E-05"
        ixy="1.77E-06"
        ixz="9E-08"
        iyy="9.68E-05"
        iyz="-4.9E-07"
        izz="9.864E-05" />
    </inertial>
    <visual>
      <origin
        xyz="0 0 0"
        rpy="0 0 0" />
      <geometry>
        <mesh
          filename="../meshes/rr_hip.STL" />
      </geometry>
      <material
        name="">
        <color
          rgba="0.75294 0.75294 0.75294 1" />
      </material>
    </visual>
    <collision>
      <origin
        xyz="-0.03515121 0.00140177 9.224E-05"
        rpy="1.57079632 0 0" />
      <geometry>
        <cylinder radius="0.028" length="0.04" />
      </geometry>
    </collision>
  </link>
  <joint
    name="rr_hip_joint"
    type="revolute">
    <origin
      xyz="-0.097 -0.04 0"
      rpy="0 0 0" />
    <parent
      link="base" />
    <child
      link="rr_hip" />
    <axis
      xyz="1 0 0" />
    <limit
      lower="-0.087222"
      upper="0.087222"
      effort="6"
      velocity="10.467" />
  </joint>
  <link
    name="rr_thigh">
    <inertial>
      <origin
        xyz="-0.00053812 -0.05495676 -0.00960878"
        rpy="0 0 0" />
      <mass
        value="0.41571" />
      <inertia
        ixx="0.00055765"
        ixy="4.5E-07"
        ixz="-6.61E-06"
        iyy="0.0004175"
        iyz="-9.783E-05"
        izz="0.00027407" />
    </inertial>
    <visual>
      <origin
        xyz="0 0 0"
        rpy="0 0 0" />
      <geometry>
        <mesh
          filename="../meshes/rr_thigh.STL" />
      </geometry>
      <material
        name="">
        <color
          rgba="0.75294 0.75294 0.75294 1" />
      </material>
    </visual>
    <collision>
      <origin
        xyz="-0.00053812 -0.05495676 -0.00960878"
        rpy="0 0 0" />
      <geometry>
        <box size="0.03 0.03 0.05" />
      </geometry>
    </collision>
  </link>
  <joint
    name="rr_thigh_joint"
    type="revolute">
    <origin
      xyz="-0.037 -0.017 0"
      rpy="0 0 0" />
    <parent
      link="rr_hip" />
    <child
      link="rr_thigh" />
    <axis
      xyz="0 1 0" />
    <limit
      lower="-2.6167"
      upper="2.6167"
      effort="6"
      velocity="10.467" />
  </joint>
  <link
    name="rr_calf">
    <inertial>
      <origin
        xyz="0.00275232 0 -0.02972173"
        rpy="0 0 0" />
      <mass
        value="0.045248" />
      <inertia
        ixx="7.175E-05"
        ixy="0"
        ixz="3.98E-06"
        iyy="7.314E-05"
        iyz="0"
        izz="3.66E-06" />
    </inertial>
    <visual>
      <origin
        xyz="0 0 0"
        rpy="0 0 0" />
      <geometry>
        <mesh
          filename="../meshes/rr_calf.STL" />
      </geometry>
      <material
        name="">
        <color
          rgba="0.75294 0.75294 0.75294 1" />
      </material>
    </visual>
    <collision>
      <origin
        xyz="0.00275232 0 -0.02972173"
        rpy="0 0 0" />
      <geometry>
        <box size="0.015 0.015 0.05" />
      </geometry>
    </collision>
  </link>
  <joint
    name="rr_calf_joint"
    type="revolute">
    <origin
      xyz="0 -0.081 -0.105"
      rpy="0 0 0" />
    <parent
      link="rr_thigh" />
    <child
      link="rr_calf" />
    <axis
      xyz="0 1 0" />
    <limit
      lower="-2.5469"
      upper="-0.48844"
      effort="6"
      velocity="10.467" />
  </joint>
  <link
    name="rr_foot">
    <inertial>
      <origin
        xyz="-0.0005743 -0.00010766 -0.0027789"
        rpy="0 0 0" />
      <mass
        value="0.014945" />
      <inertia
        ixx="1E-06"
        ixy="0"
        ixz="6E-08"
        iyy="1.06E-06"
        iyz="0"
        izz="1.3E-06" />
    </inertial>
    <visual>
      <origin
        xyz="0 0 0"
        rpy="0 0 0" />
      <geometry>
        <mesh
          filename="../meshes/rr_foot.STL" />
      </geometry>
      <material
        name="">
        <color
          rgba="0.75294 0.75294 0.75294 1" />
      </material>
    </visual>
    <collision>
      <origin
        xyz="-0.0005743 -0.00010766 -0.0027789"
        rpy="0 0 0" />
      <geometry>
        <sphere radius="0.015" />
      </geometry>
    </collision>
  </link>
  <joint
    name="rr_foot_joint"
    type="fixed">
    <origin
      xyz="0 0 -0.12589"
      rpy="0 0 0" />
    <parent
      link="rr_calf" />
    <child
      link="rr_foot" />
    <axis
      xyz="0 0 0" />
  </joint>
</robot>